<?xml version="1.0"?>
<robot xmlns:xacro="http://ros.org/wiki/xacro" name="tortoisebot">

   <link name="base_link">
   <visual>
      <geometry>
         <box size="0.6 0.3 0.3"/>
      </geometry>
      <material name="silver">
         <color rgba="0.75 0.75 0.75 1"/>
      </material>
   </visual>
   <collision>
      <geometry>
         <box size="0.6 0.3 0.3"/>
      </geometry>
   </collision>
   <inertial>
      <mass value="1.0"/>
      <inertia ixx="0.015" iyy="0.0375" izz="0.0375" ixy="0" ixz="0" iyz="0"/>
   </inertial>
   </link>

   
   <joint name="base_footprint_joint" type="fixed">
      <parent link="base_link"/>
      <child link="base_footprint"/>
      <origin xyz="0 0 -0.185" rpy="0 0 0"/>
   </joint>

   <link name = "base_footprint"/>

   <link name="front_caster">
   <visual>
      <geometry>
         <box size="0.1 0.1 0.15"/>
      </geometry>
      <material name="silver">
         <color rgba="0.75 0.75 0.75 1"/>
      </material>
   </visual>
   <collision>
      <geometry>
         <box size="0.1 0.1 0.15"/>
      </geometry>
   </collision>
   <inertial>
      <mass value="0.05"/>
      <inertia ixx="0.00013542" iyy="0.00013542" izz="0.00008333" ixy="0" ixz="0" iyz="0"/>
   </inertial>
   </link>

   <joint name="front_caster_joint" type="continuous">
      <axis xyz="0 0 1"/>
      <parent link="base_link"/>
      <child link="front_caster"/>
      <origin rpy="0 0 0" xyz="0.3 0 -0.075"/>
   </joint>

   <link name="front_wheel">
   <visual>
      <geometry>
         <cylinder length="0.05" radius="0.035"/>
      </geometry>
      <material name="black">
         <color rgba="0 0 0 1"/>
      </material>
   </visual>
   <collision>
      <geometry>
         <cylinder length="0.05" radius="0.035"/>
      </geometry>
   </collision>
   <inertial>
      <mass value="0.1"/>
      <inertia ixx="5.1458e-5" iyy="5.1458e-5" izz="6.125e-5" ixy="0" ixz="0" iyz="0"/>
   </inertial>
   </link>

   <joint name="front_wheel_joint" type="continuous">
      <axis xyz="0 0 1"/>
      <parent link="front_caster"/>
      <child link="front_wheel"/>
      <origin rpy="-1.5708 0 0" xyz="0.05 0 -.075"/>
   </joint>

   <link name="right_wheel">
   <visual>
      <geometry>
         <cylinder length="0.05" radius="0.035"/>
      </geometry>
      <material name="black">
         <color rgba="0 0 0 1"/>
      </material>
   </visual>
   <collision>
      <geometry>
         <cylinder length="0.05" radius="0.035"/>
      </geometry>
   </collision>
   <inertial>
      <mass value="0.1"/>
      <inertia ixx="5.1458e-5" iyy="5.1458e-5" izz="6.125e-5" ixy="0" ixz="0" iyz="0"/>
   </inertial>
   </link>

   <joint name="right_wheel_joint" type="continuous">
      <axis xyz="0 0 1">
         <limit>
            <effort>20</effort>
         </limit>
      </axis>
      <max_linear_acceleration>0.033</max_linear_acceleration>
      <parent link="base_link"/>
      <child link="right_wheel"/>
      <origin rpy="-1.5708 0 0" xyz="-0.2825 -0.125 -.15"/>
   </joint>

   <link name="left_wheel">
   <visual>
      <geometry>
         <cylinder length="0.05" radius="0.035"/>
      </geometry>
      <material name="black">
         <color rgba="0 0 0 1"/>
      </material>
   </visual>
   <collision>
      <geometry>
         <cylinder length="0.05" radius="0.035"/>
      </geometry>
   </collision>
   <inertial>
      <mass value="0.1"/>
      <inertia ixx="5.1458e-5" iyy="5.1458e-5" izz="6.125e-5" ixy="0" ixz="0" iyz="0"/>
   </inertial>
   </link>

   <joint name="left_wheel_joint" type="continuous">
      <axis xyz="0 0 1">
         <limit>
            <effort>20</effort>
         </limit>
      </axis>
      <max_linear_acceleration>0.033</max_linear_acceleration>
      <parent link="base_link"/>
      <child link="left_wheel"/>
      <origin rpy="-1.5708 0 0" xyz="-0.2825 0.125 -.15"/>
   </joint>

   <joint name="lidar_joint" type="fixed">
      <parent link="base_link"/>
      <child link="base_scan"/>
      <origin xyz="0.25 0 0.15" rpy="0 0 0"/>
   </joint>

   <link name="base_scan">
   <visual>
      <origin xyz="0 0 0" rpy="0 0 0"/>
      <geometry>
         <mesh filename="file://$(find robot_description)/meshes/lidar.dae"/>
      </geometry>
   </visual>
   <collision>
      <origin xyz="0 0 0" rpy="0 0 0"/>
      <geometry>
         <box size="0.1 0.1 0.1"/>
      </geometry>
   </collision>
   <inertial>
      <mass value="1e-5"/>
      <origin xyz="0 0 0" rpy="0 0 0"/>
      <inertia ixx="1e-6" ixy="0" ixz="0" iyy="1e-6" iyz="0" izz="1e-6"/>
   </inertial>

   </link>

   <link name="camera_link">
   <visual>
      <geometry>
         <box size="0.02 0.06 0.03"/>
      </geometry>
      <material name="blue">
         <color rgba="0 0 1 1"/>
      </material>
   </visual>
   <collision>
      <geometry>
         <box size="0.02 0.06 0.03"/>
      </geometry>
   </collision>
   <inertial>
      <mass value="0.05"/>
      <inertia ixx="1e-5" iyy="1e-5" izz="1e-5" ixy="0" ixz="0" iyz="0"/>
   </inertial>

   </link>

   <joint name="camera_joint" type="fixed">
      <parent link="base_link"/>
      <child link="camera_link"/>
      <origin xyz="0.31 0.0 0.06" rpy="0 0 0"/>
   </joint>

   <link name="camera_optical_frame"/>
   <joint name="camera_optical_frame_joint" type="fixed">
      <parent link="camera_link"/>
      <child link="camera_optical_frame"/>
      <origin xyz="0 0 0" rpy="-1.5708 0 -1.5708"/>
   </joint>

   <link name ="imu_link">
   <visual>
      <geometry>
         <box size="0.02 0.06 0.03"/>
      </geometry>
      <material name="red">
         <color rgba="1 0 0 1"/>
      </material>
   </visual>
   <collision>
      <geometry>
         <box size="0.02 0.06 0.03"/>
      </geometry>
   </collision>
   <inertial>
      <mass value="0.05"/>
      <inertia ixx="1e-5" iyy="1e-5" izz="1e-5" ixy="0" ixz="0" iyz="0"/>
   </inertial>

   </link>

    <joint name="imu_joint" type="fixed">
      <parent link="base_link"/>
      <child link="imu_link"/>
      <origin xyz="0.31 0.0 0.1" rpy="0 0 0"/>
   </joint>

  <gazebo>
      <plugin
         filename="gz-sim-diff-drive-system"
         name="gz::sim::systems::DiffDrive">
         <left_joint>left_wheel_joint</left_joint>
         <right_joint>right_wheel_joint</right_joint>
         <wheel_separation>0.25</wheel_separation>
         <wheel_radius>0.035</wheel_radius>
         <topic>cmd_vel</topic>
         <max_linear_acceleration>0.1</max_linear_acceleration>
         <odom_topic>odom</odom_topic>
         <frame_id>odom</frame_id>
         <child_frame_id>base_link</child_frame_id>
         <odom_publisher_frequency>30</odom_publisher_frequency>
         <tf_topic>/tf</tf_topic>
      </plugin>

      <plugin filename="gz-sim-joint-state-publisher-system"
         name="gz::sim::systems::JointStatePublisher">
         <topic>joint_states</topic>
         <joint_name>left_wheel_joint</joint_name>
         <joint_name>right_wheel_joint</joint_name>
      </plugin>
    </gazebo>

    <gazebo reference = "imu_link">
    <sensor name="tb3_imu" type="imu">
    <always_on>true</always_on>
    <update_rate>200</update_rate>
    <gz_frame_id>imu_link</gz_frame_id>
    <topic>imu</topic>
    <imu>
     <angular_velocity>
            <x>
              <noise type="gaussian">
                <mean>0.0</mean>
                <stddev>2e-4</stddev>
              </noise>
            </x>
            <y>
              <noise type="gaussian">
                <mean>0.0</mean>
                <stddev>2e-4</stddev>
              </noise>
            </y>
            <z>
              <noise type="gaussian">
                <mean>0.0</mean>
                <stddev>2e-4</stddev>
              </noise>
            </z>
          </angular_velocity>
          <linear_acceleration>
            <x>
              <noise type="gaussian">
                <mean>0.0</mean>
                <stddev>1.7e-2</stddev>
              </noise>
            </x>
            <y>
              <noise type="gaussian">
                <mean>0.0</mean>
                <stddev>1.7e-2</stddev>
              </noise>
            </y>
            <z>
              <noise type="gaussian">
                <mean>0.0</mean>
                <stddev>1.7e-2</stddev>
              </noise>
            </z>
          </linear_acceleration>
    </imu>
  </sensor>
  </gazebo>

  <gazebo reference="camera_link">
  <sensor name="mycamera" type="rgbd_camera">
         <always_on>1</always_on>
         <update_rate>10</update_rate>
         <visualize>true</visualize>
         <topic>depth_camera</topic>
         <gz_frame_id>camera_optical_frame</gz_frame_id>
         <camera name="mycamera1">
          <camera_info_topic>depth_camera/camera_info</camera_info_topic>
            <horizontal_fov>1.02974</horizontal_fov>
            <image>
               <width>640</width>
               <height>480</height>
            </image>
            <clip>
               <near>0.1</near>
               <far>4</far>
            </clip>
            <optical_frame_id>camera_optical_frame</optical_frame_id>
         </camera>
      </sensor>
      </gazebo>

  <gazebo reference="base_scan">
    <sensor name="hls_lfcd_lds" type="gpu_lidar">
         <always_on>true</always_on>
         <visualize>true</visualize>
         <pose>0 0 0 0 0 0</pose>
         <update_rate>10</update_rate>
         <topic>scan</topic>
         <gz_frame_id>base_scan</gz_frame_id>
         <lidar>
            <scan>
               <horizontal>
                  <samples>180</samples>
                  <update_rate>10</update_rate>
                  <min_angle>-3.14159</min_angle>
                  <max_angle>3.14159</max_angle>
               </horizontal>
            </scan>
            <range>
               <min>0.1</min>
               <max>20</max>
               <resolution>0.015</resolution>
            </range>
            <noise>
               <type>gaussian</type>
               <mean>0.0</mean>
               <stddev>0.01</stddev>
            </noise>
         </lidar>
      </sensor>
      </gazebo>

</robot>


